<?xml version="1.0" ?>
<sdf version="1.9">
<model name="auv" canonical_link="hydrogen_frame"> 
<static>false</static>

<link name="hydrogen_frame">
  <pose>1.8179 -22.3704 -0.3269 0 0 0</pose>

  <inertial>
    <mass>4.8</mass>
    <pose>0 0 0 0 0 0</pose>
    <inertia>
      <ixx>0.029</ixx>
      <ixy>0.0</ixy>
      <ixz>0.0</ixz>
      <iyy>0.044</iyy>
      <iyz>0.0</iyz>
      <izz>0.044</izz>
    </inertia>
  </inertial>

  <visual name="frame_visual">
    <geometry>
      <mesh>
        <uri>auv2.stl</uri>
        <scale>0.001 0.001 0.001</scale>
      </mesh>
    </geometry>
    <material>
      <ambient>0.4 0.4 0.4 1</ambient>
      <diffuse>0.4 0.4 0.4 1</diffuse>
    </material>
  </visual>

  <collision name="frame_collision">
    <geometry>
      <mesh>
        <uri>auv2.stl</uri>
        <scale>0.001 0.001 0.001</scale>
      </mesh>
    </geometry>
  </collision>

  <sensor name="imu_sensor" type="imu">
    <always_on>1</always_on>
    <update_rate>1</update_rate>
    <visualize>true</visualize>
    <topic>imu</topic>
  </sensor>
</link>

<link name="front_propeller">
  <pose relative_to="hydrogen_frame">-0.24 -0.00725 0 0 0 0</pose>
  <inertial>
    <mass>0.1</mass>
    <inertia>
      <ixx>0.00043333</ixx>
      <ixy>0</ixy>
      <ixz>0</ixz>
      <iyy>0.00043333</iyy>
      <iyz>0</iyz>
      <izz>0.0008</izz>
    </inertia>
  </inertial>
  <visual name="front_propeller_visual">
    <geometry>
      <mesh>
        <uri>propellervertical.stl</uri>
        <scale>0.0001 0.0001 0.0001</scale>
      </mesh>
    </geometry>
    <material>
      <ambient>0.1 0.1 0.1 1</ambient>
      <diffuse>0.1 0.1 0.1 1</diffuse>
    </material>
  </visual>
  <collision name="front_propeller_collision">
    <geometry>
      <mesh>
        <uri>propellervertical.stl</uri>
        <scale>0.0001 0.0001 0.0001</scale>
      </mesh>
    </geometry>
  </collision>
</link>

<link name="right_propeller_1">
  <pose relative_to="hydrogen_frame">-0.0527 0.1734 0.016 0 0 0</pose>
  <inertial>
    <mass>0.1</mass>
    <inertia>
      <ixx>0.00043333</ixx>
      <ixy>0</ixy>
      <ixz>0</ixz>
      <iyy>0.00043333</iyy>
      <iyz>0</iyz>
      <izz>0.0008</izz>
    </inertia>
  </inertial>
  <visual name="right_propeller_1_visual">
    <geometry>
      <mesh>
        <uri>propeller.stl</uri>
        <scale>0.001 0.001 0.001</scale>
      </mesh>
    </geometry>
    <material>
      <ambient>0.1 0.1 0.1 1</ambient>
      <diffuse>0.1 0.1 0.1 1</diffuse>
    </material>
  </visual>
  <collision name="right_propeller_1_collision">
    <geometry>
      <mesh>
        <uri>propeller.stl</uri>
        <scale>0.001 0.001 0.001</scale>
      </mesh>
    </geometry>
  </collision>
</link>

<link name="right_propeller_2">
  <pose relative_to="hydrogen_frame">0.0527 0.1734 0 0 0 0</pose>
  <inertial>
    <mass>0.1</mass>
    <inertia>
      <ixx>0.00043333</ixx>
      <ixy>0</ixy>
      <ixz>0</ixz>
      <iyy>0.00043333</iyy>
      <iyz>0</iyz>
      <izz>0.0008</izz>
    </inertia>
  </inertial>
  <visual name="right_propeller_2_visual">
    <geometry>
      <mesh>
        <uri>propellervertical.stl</uri>
        <scale>0.0001 0.0001 0.0001</scale>
      </mesh>
    </geometry>
    <material>
      <ambient>0.1 0.1 0.1 1</ambient>
      <diffuse>0.1 0.1 0.1 1</diffuse>
    </material>
  </visual>
  <collision name="right_propeller_2_collision">
    <geometry>
      <mesh>
        <uri>propellervertical.stl</uri>
        <scale>0.0001 0.0001 0.0001</scale>
      </mesh>
    </geometry>
  </collision>
</link>

<link name="left_propeller_1">
  <pose relative_to="hydrogen_frame">-0.0527 -0.1734 0.016 0 0 0</pose>
  <inertial>
    <mass>0.1</mass>
    <inertia>
      <ixx>0.00043333</ixx>
      <ixy>0</ixy>
      <ixz>0</ixz>
      <iyy>0.00043333</iyy>
      <iyz>0</iyz>
      <izz>0.0008</izz>
    </inertia>
  </inertial>
  <visual name="left_propeller_1_visual">
    <geometry>
      <mesh>
        <uri>propeller.stl</uri>
        <scale>0.001 0.001 0.001</scale>
      </mesh>
    </geometry>
    <material>
      <ambient>0.1 0.1 0.1 1</ambient>
      <diffuse>0.1 0.1 0.1 1</diffuse>
    </material>
  </visual>
  <collision name="left_propeller_1_collision">
    <geometry>
      <mesh>
        <uri>propeller.stl</uri>
        <scale>0.001 0.001 0.001</scale>
      </mesh>
    </geometry>
  </collision>
</link>

<link name="left_propeller_2">
  <pose relative_to="hydrogen_frame">0.0527 -0.1734 0 0 0 0</pose>
  <inertial>
    <mass>0.1</mass>
    <inertia>
      <ixx>0.00043333</ixx>
      <ixy>0</ixy>
      <ixz>0</ixz>
      <iyy>0.00043333</iyy>
      <iyz>0</iyz>
      <izz>0.0008</izz>
    </inertia>
  </inertial>
  <visual name="left_propeller_2_visual">
    <geometry>
      <mesh>
        <uri>propellervertical.stl</uri>
        <scale>0.0001 0.0001 0.0001</scale>
      </mesh>
    </geometry>
    <material>
      <ambient>0.1 0.1 0.1 1</ambient>
      <diffuse>0.1 0.1 0.1 1</diffuse>
    </material>
  </visual>
  <collision name="left_propeller_2_collision">
    <geometry>
      <mesh>
        <uri>propellervertical.stl</uri>
        <scale>0.0001 0.0001 0.0001</scale>
      </mesh>
    </geometry>
  </collision>
</link>

<joint name="front_propeller_joint" type="revolute">
  <parent>hydrogen_frame</parent>
  <child>front_propeller</child>
  <axis>
    <xyz expressed_in="__model__">0 0 1</xyz>
    <limit>
      <lower>-1e16</lower>
      <upper>1e16</upper>
      <velocity>100</velocity>
    </limit>
  </axis>
</joint>

<joint name="left_propeller_1_joint" type="revolute">
  <parent>hydrogen_frame</parent>
  <child>left_propeller_1</child>
  <axis>
    <xyz expressed_in="__model__">0 1 0</xyz>
    <limit>
      <lower>-1e16</lower>
      <upper>1e16</upper>
      <velocity>100</velocity>
    </limit>
  </axis>
</joint>

<joint name="left_propeller_2_joint" type="revolute">
  <parent>hydrogen_frame</parent>
  <child>left_propeller_2</child>
  <axis>
    <xyz expressed_in="__model__">0 1 0</xyz>
    <limit>
      <lower>-1e16</lower>
      <upper>1e16</upper>
      <velocity>100</velocity>
    </limit>
  </axis>
</joint>

<joint name="right_propeller_1_joint" type="revolute">
  <parent>hydrogen_frame</parent>
  <child>right_propeller_1</child>
  <axis>
    <xyz expressed_in="__model__">0 0 1</xyz>
    <limit>
      <lower>-1e16</lower>
      <upper>1e16</upper>
      <velocity>100</velocity>
    </limit>
  </axis>
</joint>

<joint name="right_propeller_2_joint" type="revolute">
  <parent>hydrogen_frame</parent>
  <child>right_propeller_2</child>
  <axis>
    <xyz expressed_in="__model__">0 1 0</xyz>
    <limit>
      <lower>-1e16</lower>
      <upper>1e16</upper>
      <velocity>100</velocity>
    </limit>
  </axis>
</joint>

<!-- ========================= FRONT CAMERA ========================= -->

<link name="zed_camera_front_link">
  <pose relative_to="hydrogen_frame">0.162 0 0.016 0 0 0</pose>
  <visual name="zed_camera_front_visual">
    <geometry>
      <mesh><uri>zed2i.stl</uri></mesh>
    </geometry>
  </visual>
  <collision name="zed_camera_front_collision">
    <geometry>
      <mesh><uri>zed2i.stl</uri></mesh>
    </geometry>
  </collision>
</link>

<joint name='front_camera_frame_joint' type='fixed'>
<parent>hydrogen_frame</parent>
<child>zed_camera_front_link</child>
</joint>

<!-- ========================= DOWN CAMERA ========================= -->

<link name="zed_camera_down_link">
  <pose relative_to="hydrogen_frame">0.05 0 -0.08 0 1.5708 0</pose>
  <visual name="zed_camera_down_visual">
    <geometry>
    <mesh><uri>zed2i.stl</uri></mesh>
    </geometry>
  </visual>
  <collision name="zed_camera_down_collision">
    <geometry>
      <mesh><uri>zed2i.stl</uri></mesh>
    </geometry>
  </collision>
</link>

<joint name='down_camera_frame_joint' type='fixed'>
<parent>hydrogen_frame</parent>
<child>zed_camera_down_link</child>
</joint>

</model> 
</sdf>

